<?xml version="1.0" ?>
<!-- Generated using onshape-to-robot -->
<!-- Onshape https://cad.onshape.com/documents/435b824f8426b3b8f2a8a9e0/w/f13a2bb43b056c76b67cc2b3/e/86f1e349b89a5f0b7c9e231f -->
<robot name="C:\Users\epfis\Documents\NU robotics hand\hand teleop\hand_urdf">
  <!-- Link base -->
  <link name="base">
    <inertial>
      <origin xyz="0 0 0" rpy="0 0 0"/>
      <mass value="1e-09"/>
      <inertia ixx="1e-09" ixy="0" ixz="0" iyy="1e-09" iyz="0" izz="1e-09"/>
    </inertial>
    <!-- Part base -->
    <visual>
      <origin xyz="0.0161891 0.00137668 0.00812779" rpy="-3.42121e-30 1.60982e-15 -1.5708"/>
      <geometry>
        <mesh filename="package://assets\base.stl"/>
      </geometry>
      <material name="base_material">
        <color rgba="0.615686 0.811765 0.929412 1"/>
      </material>
    </visual>
    <collision>
      <origin xyz="0.0161891 0.00137668 0.00812779" rpy="-3.42121e-30 1.60982e-15 -1.5708"/>
      <geometry>
        <mesh filename="package://assets\base.stl"/>
      </geometry>
    </collision>
  </link>
  <!-- Link intermediate_link -->
  <link name="intermediate_link">
    <inertial>
      <origin xyz="0 0 0" rpy="0 0 0"/>
      <mass value="1e-09"/>
      <inertia ixx="1e-09" ixy="0" ixz="0" iyy="1e-09" iyz="0" izz="1e-09"/>
    </inertial>
    <!-- Part intermediate_link -->
    <visual>
      <origin xyz="0.0682324 -0.00935237 0.0358367" rpy="1.58872 1.5708 0"/>
      <geometry>
        <mesh filename="package://assets\intermediate_link.stl"/>
      </geometry>
      <material name="intermediate_link_material">
        <color rgba="0.980392 0.713725 0.00392157 1"/>
      </material>
    </visual>
    <collision>
      <origin xyz="0.0682324 -0.00935237 0.0358367" rpy="1.58872 1.5708 0"/>
      <geometry>
        <mesh filename="package://assets\intermediate_link.stl"/>
      </geometry>
    </collision>
  </link>
  <!-- Link palm_solid -->
  <link name="palm_solid">
    <inertial>
      <origin xyz="0 0 0" rpy="0 0 0"/>
      <mass value="1e-09"/>
      <inertia ixx="1e-09" ixy="0" ixz="0" iyy="1e-09" iyz="0" izz="1e-09"/>
    </inertial>
    <!-- Part palm_solid -->
    <visual>
      <origin xyz="0.0430364 0.00890065 -0.0355367" rpy="-1.55287 -1.5708 0"/>
      <geometry>
        <mesh filename="package://assets\palm_solid.stl"/>
      </geometry>
      <material name="palm_solid_material">
        <color rgba="0.27451 0.270588 0.266667 1"/>
      </material>
    </visual>
    <collision>
      <origin xyz="0.0430364 0.00890065 -0.0355367" rpy="-1.55287 -1.5708 0"/>
      <geometry>
        <mesh filename="package://assets\palm_solid.stl"/>
      </geometry>
    </collision>
  </link>
  <!-- Link thumb_intermediate_v1 -->
  <link name="thumb_intermediate_v1">
    <inertial>
      <origin xyz="0 0 0" rpy="0 0 0"/>
      <mass value="1e-09"/>
      <inertia ixx="1e-09" ixy="0" ixz="0" iyy="1e-09" iyz="0" izz="1e-09"/>
    </inertial>
    <!-- Part thumb_intermediate_v1 -->
    <visual>
      <origin xyz="-0.00989613 -0.00238569 0.000259753" rpy="-1.31743 0.17263 7.86009e-18"/>
      <geometry>
        <mesh filename="package://assets\thumb_intermediate_v1.stl"/>
      </geometry>
      <material name="thumb_intermediate_v1_material">
        <color rgba="0.27451 0.270588 0.266667 1"/>
      </material>
    </visual>
    <collision>
      <origin xyz="-0.00989613 -0.00238569 0.000259753" rpy="-1.31743 0.17263 7.86009e-18"/>
      <geometry>
        <mesh filename="package://assets\thumb_intermediate_v1.stl"/>
      </geometry>
    </collision>
  </link>
  <!-- Link thumb_palm_section -->
  <link name="thumb_palm_section">
    <inertial>
      <origin xyz="0 0 0" rpy="0 0 0"/>
      <mass value="1e-09"/>
      <inertia ixx="1e-09" ixy="0" ixz="0" iyy="1e-09" iyz="0" izz="1e-09"/>
    </inertial>
    <!-- Part thumb_palm_section -->
    <visual>
      <origin xyz="-0.0217843 0.00434121 0.000740247" rpy="1.82417 -0.17263 -1.26524e-17"/>
      <geometry>
        <mesh filename="package://assets\thumb_palm_section.stl"/>
      </geometry>
      <material name="thumb_palm_section_material">
        <color rgba="0.627451 0.627451 0.627451 1"/>
      </material>
    </visual>
    <collision>
      <origin xyz="-0.0217843 0.00434121 0.000740247" rpy="1.82417 -0.17263 -1.26524e-17"/>
      <geometry>
        <mesh filename="package://assets\thumb_palm_section.stl"/>
      </geometry>
    </collision>
  </link>
  <!-- Link thumb_middle -->
  <link name="thumb_middle">
    <inertial>
      <origin xyz="0 0 0" rpy="0 0 0"/>
      <mass value="1e-09"/>
      <inertia ixx="1e-09" ixy="0" ixz="0" iyy="1e-09" iyz="0" izz="1e-09"/>
    </inertial>
    <!-- Part thumb_middle -->
    <visual>
      <origin xyz="-0.0477856 -0.00705829 -0.00679029" rpy="0.273385 0.114287 1.41009e-17"/>
      <geometry>
        <mesh filename="package://assets\thumb_middle.stl"/>
      </geometry>
      <material name="thumb_middle_material">
        <color rgba="0.627451 0.627451 0.627451 1"/>
      </material>
    </visual>
    <collision>
      <origin xyz="-0.0477856 -0.00705829 -0.00679029" rpy="0.273385 0.114287 1.41009e-17"/>
      <geometry>
        <mesh filename="package://assets\thumb_middle.stl"/>
      </geometry>
    </collision>
  </link>
  <!-- Link thumb_middle_2 -->
  <link name="thumb_middle_2">
    <inertial>
      <origin xyz="0 0 0" rpy="0 0 0"/>
      <mass value="1e-09"/>
      <inertia ixx="1e-09" ixy="0" ixz="0" iyy="1e-09" iyz="0" izz="1e-09"/>
    </inertial>
    <!-- Part thumb_middle_2 -->
    <visual>
      <origin xyz="-0.0592938 -0.00820927 0.0104142" rpy="-1.31743 0.17263 -1.14344e-17"/>
      <geometry>
        <mesh filename="package://assets\thumb_middle__2.stl"/>
      </geometry>
      <material name="thumb_middle_2_material">
        <color rgba="0.647059 0.647059 0.647059 1"/>
      </material>
    </visual>
    <collision>
      <origin xyz="-0.0592938 -0.00820927 0.0104142" rpy="-1.31743 0.17263 -1.14344e-17"/>
      <geometry>
        <mesh filename="package://assets\thumb_middle__2.stl"/>
      </geometry>
    </collision>
  </link>
  <!-- Link thumb_tip -->
  <link name="thumb_tip">
    <inertial>
      <origin xyz="0 0 0" rpy="0 0 0"/>
      <mass value="1e-09"/>
      <inertia ixx="1e-09" ixy="0" ixz="0" iyy="1e-09" iyz="0" izz="1e-09"/>
    </inertial>
    <!-- Part thumb_tip -->
    <visual>
      <origin xyz="-0.0791251 -0.0108018 0.0122142" rpy="-1.31743 0.17263 -1.92026e-17"/>
      <geometry>
        <mesh filename="package://assets\thumb_tip.stl"/>
      </geometry>
      <material name="thumb_tip_material">
        <color rgba="0.27451 0.270588 0.266667 1"/>
      </material>
    </visual>
    <collision>
      <origin xyz="-0.0791251 -0.0108018 0.0122142" rpy="-1.31743 0.17263 -1.92026e-17"/>
      <geometry>
        <mesh filename="package://assets\thumb_tip.stl"/>
      </geometry>
    </collision>
  </link>
  <!-- Joint from thumb_middle_2 to thumb_tip -->
  <joint name="thumb_4" type="revolute">
    <origin xyz="0.0198655 0.00231518 -0.00175" rpy="7.41283e-15 -1.59703e-14 -1.60298e-15"/>
    <parent link="thumb_middle_2"/>
    <child link="thumb_tip"/>
    <axis xyz="0 0 1"/>
    <limit effort="10" velocity="10" lower="0" upper="1.5708"/>
  </joint>
  <!-- Joint from thumb_middle to thumb_middle_2 -->
  <joint name="thumb_3" type="revolute">
    <origin xyz="0.0128901 -0.0075423 -0.0055" rpy="1.5708 0.115493 -0.173775"/>
    <parent link="thumb_middle"/>
    <child link="thumb_middle_2"/>
    <axis xyz="0 0 1"/>
    <limit effort="10" velocity="10" lower="-0.000526075" upper="1.57027"/>
  </joint>
  <!-- Joint from thumb_palm_section to thumb_middle -->
  <joint name="thumb_abd" type="revolute">
    <origin xyz="0.0230132 -0.00731315 0.0159544" rpy="1.5708 -0.174152 -0.116019"/>
    <parent link="thumb_palm_section"/>
    <child link="thumb_middle"/>
    <axis xyz="0 0 1"/>
    <limit effort="10" velocity="10" lower="-1.57117" upper="0.174156"/>
  </joint>
  <!-- Joint from thumb_intermediate_v1 to thumb_palm_section -->
  <joint name="thumb_2" type="revolute">
    <origin xyz="0.0118882 0.00195552 6.93889e-18" rpy="-3.14159 2.56139e-15 0.0328482"/>
    <parent link="thumb_intermediate_v1"/>
    <child link="thumb_palm_section"/>
    <axis xyz="0 0 1"/>
    <limit effort="10" velocity="10" lower="-3.141592653589793" upper="3.141592653589793"/>
    <mimic joint="thumb_1" multiplier="-1.0"/>
  </joint>
  <!-- Joint from palm_solid to thumb_intermediate_v1 -->
  <joint name="thumb_1" type="revolute">
    <origin xyz="0.0413225 0.0120631 -0.0257823" rpy="-2.95542 -1.3951 2.71713"/>
    <parent link="palm_solid"/>
    <child link="thumb_intermediate_v1"/>
    <axis xyz="0 0 1"/>
    <limit effort="10" velocity="10" lower="-0.0328482" upper="0.75255"/>
  </joint>
  <!-- Link finger_intermediate -->
  <link name="finger_intermediate">
    <inertial>
      <origin xyz="0 0 0" rpy="0 0 0"/>
      <mass value="1e-09"/>
      <inertia ixx="1e-09" ixy="0" ixz="0" iyy="1e-09" iyz="0" izz="1e-09"/>
    </inertial>
    <!-- Part finger_intermediate -->
    <visual>
      <origin xyz="0.0164705 -0.0600499 -0.0337993" rpy="-0.25043 1.21142 -2.77186e-17"/>
      <geometry>
        <mesh filename="package://assets\finger_intermediate.stl"/>
      </geometry>
      <material name="finger_intermediate_material">
        <color rgba="0.231373 0.380392 0.705882 1"/>
      </material>
    </visual>
    <collision>
      <origin xyz="0.0164705 -0.0600499 -0.0337993" rpy="-0.25043 1.21142 -2.77186e-17"/>
      <geometry>
        <mesh filename="package://assets\finger_intermediate.stl"/>
      </geometry>
    </collision>
  </link>
  <!-- Link pinky_finger_middle -->
  <link name="pinky_finger_middle">
    <inertial>
      <origin xyz="0 0 0" rpy="0 0 0"/>
      <mass value="1e-09"/>
      <inertia ixx="1e-09" ixy="0" ixz="0" iyy="1e-09" iyz="0" izz="1e-09"/>
    </inertial>
    <!-- Part pinky_finger_middle -->
    <visual>
      <origin xyz="0.0196463 0.0716718 0.0337993" rpy="2.89116 -1.21142 -5.65583e-17"/>
      <geometry>
        <mesh filename="package://assets\pinky_finger_middle.stl"/>
      </geometry>
      <material name="pinky_finger_middle_material">
        <color rgba="0.27451 0.270588 0.266667 1"/>
      </material>
    </visual>
    <collision>
      <origin xyz="0.0196463 0.0716718 0.0337993" rpy="2.89116 -1.21142 -5.65583e-17"/>
      <geometry>
        <mesh filename="package://assets\pinky_finger_middle.stl"/>
      </geometry>
    </collision>
  </link>
  <!-- Link pinky_finger_tip -->
  <link name="pinky_finger_tip">
    <inertial>
      <origin xyz="0 0 0" rpy="0 0 0"/>
      <mass value="1e-09"/>
      <inertia ixx="1e-09" ixy="0" ixz="0" iyy="1e-09" iyz="0" izz="1e-09"/>
    </inertial>
    <!-- Part pinky_finger_tip -->
    <visual>
      <origin xyz="0.0262361 -0.0957876 -0.0337993" rpy="-0.25043 1.21142 -4.25333e-17"/>
      <geometry>
        <mesh filename="package://assets\pinky_finger_tip.stl"/>
      </geometry>
      <material name="pinky_finger_tip_material">
        <color rgba="0.27451 0.270588 0.266667 1"/>
      </material>
    </visual>
    <collision>
      <origin xyz="0.0262361 -0.0957876 -0.0337993" rpy="-0.25043 1.21142 -4.25333e-17"/>
      <geometry>
        <mesh filename="package://assets\pinky_finger_tip.stl"/>
      </geometry>
    </collision>
  </link>
  <!-- Joint from pinky_finger_middle to pinky_finger_tip -->
  <joint name="pinky_3" type="revolute">
    <origin xyz="-0.00658981 -0.0241159 4.16334e-17" rpy="-3.14159 3.69465e-16 0.0790727"/>
    <parent link="pinky_finger_middle"/>
    <child link="pinky_finger_tip"/>
    <axis xyz="0 0 1"/>
    <limit effort="10" velocity="10" lower="-1.84079" upper="0.0790727"/>
  </joint>
  <!-- Joint from finger_intermediate to pinky_finger_middle -->
  <joint name="pinky_2" type="revolute">
    <origin xyz="-0.00317575 0.0116219 -4.16334e-17" rpy="-3.14159 4.813e-16 -1.01983e-17"/>
    <parent link="finger_intermediate"/>
    <child link="pinky_finger_middle"/>
    <axis xyz="0 0 1"/>
    <limit effort="10" velocity="10" lower="-3.01981e-14" upper="0.785398"/>
    <mimic joint="pinky_1" multiplier="-1.0"/>
  </joint>
  <!-- Joint from palm_solid to finger_intermediate -->
  <joint name="pinky_1" type="revolute">
    <origin xyz="0.101782 0.0211417 -0.0731018" rpy="-3.14159 -0.359375 1.83915"/>
    <parent link="palm_solid"/>
    <child link="finger_intermediate"/>
    <axis xyz="0 0 1"/>
    <limit effort="10" velocity="10" lower="-0.785398" upper="3.01981e-14"/>
  </joint>
  <!-- Link index_finger_intermediate -->
  <link name="index_finger_intermediate">
    <inertial>
      <origin xyz="0 0 0" rpy="0 0 0"/>
      <mass value="1e-09"/>
      <inertia ixx="1e-09" ixy="0" ixz="0" iyy="1e-09" iyz="0" izz="1e-09"/>
    </inertial>
    <!-- Part index_finger_intermediate -->
    <visual>
      <origin xyz="-0.0611244 -0.0420268 0.0174182" rpy="1.04885 1.48361 1.07074e-16"/>
      <geometry>
        <mesh filename="package://assets\index_finger_intermediate.stl"/>
      </geometry>
      <material name="index_finger_intermediate_material">
        <color rgba="0.615686 0.811765 0.929412 1"/>
      </material>
    </visual>
    <collision>
      <origin xyz="-0.0611244 -0.0420268 0.0174182" rpy="1.04885 1.48361 1.07074e-16"/>
      <geometry>
        <mesh filename="package://assets\index_finger_intermediate.stl"/>
      </geometry>
    </collision>
  </link>
  <!-- Link hand_v2_index_finger_middle_v1 -->
  <link name="hand_v2_index_finger_middle_v1">
    <inertial>
      <origin xyz="0 0 0" rpy="0 0 0"/>
      <mass value="1e-09"/>
      <inertia ixx="1e-09" ixy="0" ixz="0" iyy="1e-09" iyz="0" izz="1e-09"/>
    </inertial>
    <!-- Part hand_v2_index_finger_middle_v1 -->
    <visual>
      <origin xyz="-0.0715781 -0.0480165 0.0274182" rpy="1.04885 1.48361 1.69974e-16"/>
      <geometry>
        <mesh filename="package://assets\hand_v2_index_finger_middle_v1.stl"/>
      </geometry>
      <material name="hand_v2_index_finger_middle_v1_material">
        <color rgba="0.27451 0.270588 0.266667 1"/>
      </material>
    </visual>
    <collision>
      <origin xyz="-0.0715781 -0.0480165 0.0274182" rpy="1.04885 1.48361 1.69974e-16"/>
      <geometry>
        <mesh filename="package://assets\hand_v2_index_finger_middle_v1.stl"/>
      </geometry>
    </collision>
  </link>
  <!-- Link hand_v2_index_finger_tip_v1 -->
  <link name="hand_v2_index_finger_tip_v1">
    <inertial>
      <origin xyz="0 0 0" rpy="0 0 0"/>
      <mass value="1e-09"/>
      <inertia ixx="1e-09" ixy="0" ixz="0" iyy="1e-09" iyz="0" izz="1e-09"/>
    </inertial>
    <!-- Part hand_v2_index_finger_tip_v1 -->
    <visual>
      <origin xyz="-0.0932697 0.0604451 -0.0274182" rpy="-2.09275 -1.48361 -1.68817e-17"/>
      <geometry>
        <mesh filename="package://assets\hand_v2_index_finger_tip_v1.stl"/>
      </geometry>
      <material name="hand_v2_index_finger_tip_v1_material">
        <color rgba="0.27451 0.270588 0.266667 1"/>
      </material>
    </visual>
    <collision>
      <origin xyz="-0.0932697 0.0604451 -0.0274182" rpy="-2.09275 -1.48361 -1.68817e-17"/>
      <geometry>
        <mesh filename="package://assets\hand_v2_index_finger_tip_v1.stl"/>
      </geometry>
    </collision>
  </link>
  <!-- Joint from hand_v2_index_finger_middle_v1 to hand_v2_index_finger_tip_v1 -->
  <joint name="index_3" type="revolute">
    <origin xyz="0.0216917 0.0124287 -7.28584e-17" rpy="3.14159 -3.2256e-16 -0.0841501"/>
    <parent link="hand_v2_index_finger_middle_v1"/>
    <child link="hand_v2_index_finger_tip_v1"/>
    <axis xyz="0 0 1"/>
    <limit effort="10" velocity="10" lower="-0.0841501" upper="1.83571"/>
  </joint>
  <!-- Joint from index_finger_intermediate to hand_v2_index_finger_middle_v1 -->
  <joint name="index_2" type="revolute">
    <origin xyz="0.0104536 0.00598961 -0.01" rpy="2.83784e-15 3.4643e-16 3.21483e-17"/>
    <parent link="index_finger_intermediate"/>
    <child link="hand_v2_index_finger_middle_v1"/>
    <axis xyz="0 0 1"/>
    <limit effort="10" velocity="10" lower="-0.785398" upper="1.24345e-14"/>
    <mimic joint="index_1" multiplier="1.0"/>
  </joint>
  <!-- Joint from palm_solid to index_finger_intermediate -->
  <joint name="index_1" type="revolute">
    <origin xyz="0.115479 0.00309608 -0.0129949" rpy="-3.14159 -0.0871834 0.539876"/>
    <parent link="palm_solid"/>
    <child link="index_finger_intermediate"/>
    <axis xyz="0 0 1"/>
    <limit effort="10" velocity="10" lower="-0.785398" upper="1.24345e-14"/>
  </joint>
  <!-- Link middle_finger_intermediate -->
  <link name="middle_finger_intermediate">
    <inertial>
      <origin xyz="0 0 0" rpy="0 0 0"/>
      <mass value="1e-09"/>
      <inertia ixx="1e-09" ixy="0" ixz="0" iyy="1e-09" iyz="0" izz="1e-09"/>
    </inertial>
    <!-- Part middle_finger_intermediate -->
    <visual>
      <origin xyz="-0.00399892 -0.0775232 -0.000461794" rpy="0.103486 1.41091 1.13575e-17"/>
      <geometry>
        <mesh filename="package://assets\middle_finger_intermediate.stl"/>
      </geometry>
      <material name="middle_finger_intermediate_material">
        <color rgba="0.980392 0.713725 0.00392157 1"/>
      </material>
    </visual>
    <collision>
      <origin xyz="-0.00399892 -0.0775232 -0.000461794" rpy="0.103486 1.41091 1.13575e-17"/>
      <geometry>
        <mesh filename="package://assets\middle_finger_intermediate.stl"/>
      </geometry>
    </collision>
  </link>
  <!-- Link hand_v2_middle_finger_middle_v1 -->
  <link name="hand_v2_middle_finger_middle_v1">
    <inertial>
      <origin xyz="0 0 0" rpy="0 0 0"/>
      <mass value="1e-09"/>
      <inertia ixx="1e-09" ixy="0" ixz="0" iyy="1e-09" iyz="0" izz="1e-09"/>
    </inertial>
    <!-- Part hand_v2_middle_finger_middle_v1 -->
    <visual>
      <origin xyz="-0.00525939 0.0895051 0.000461794" rpy="-3.03811 -1.41091 -2.0422e-17"/>
      <geometry>
        <mesh filename="package://assets\hand_v2_middle_finger_middle_v1.stl"/>
      </geometry>
      <material name="hand_v2_middle_finger_middle_v1_material">
        <color rgba="0.27451 0.270588 0.266667 1"/>
      </material>
    </visual>
    <collision>
      <origin xyz="-0.00525939 0.0895051 0.000461794" rpy="-3.03811 -1.41091 -2.0422e-17"/>
      <geometry>
        <mesh filename="package://assets\hand_v2_middle_finger_middle_v1.stl"/>
      </geometry>
    </collision>
  </link>
  <!-- Link hand_v2_middle_finger_tip_v1 -->
  <link name="hand_v2_middle_finger_tip_v1">
    <inertial>
      <origin xyz="0 0 0" rpy="0 0 0"/>
      <mass value="1e-09"/>
      <inertia ixx="1e-09" ixy="0" ixz="0" iyy="1e-09" iyz="0" izz="1e-09"/>
    </inertial>
    <!-- Part hand_v2_middle_finger_tip_v1 -->
    <visual>
      <origin xyz="-0.00787492 0.114368 -0.00953821" rpy="-3.03811 -1.41091 -1.37011e-17"/>
      <geometry>
        <mesh filename="package://assets\hand_v2_middle_finger_tip_v1.stl"/>
      </geometry>
      <material name="hand_v2_middle_finger_tip_v1_material">
        <color rgba="0.27451 0.270588 0.266667 1"/>
      </material>
    </visual>
    <collision>
      <origin xyz="-0.00787492 0.114368 -0.00953821" rpy="-3.03811 -1.41091 -1.37011e-17"/>
      <geometry>
        <mesh filename="package://assets\hand_v2_middle_finger_tip_v1.stl"/>
      </geometry>
    </collision>
  </link>
  <!-- Joint from hand_v2_middle_finger_middle_v1 to hand_v2_middle_finger_tip_v1 -->
  <joint name="middle_3" type="revolute">
    <origin xyz="0.00261552 -0.0248628 0.01" rpy="-3.60087e-15 1.21213e-14 0.0833933"/>
    <parent link="hand_v2_middle_finger_middle_v1"/>
    <child link="hand_v2_middle_finger_tip_v1"/>
    <axis xyz="0 0 1"/>
    <limit effort="10" velocity="10" lower="-0.0833933" upper="1.83647"/>
  </joint>
  <!-- Joint from middle_finger_intermediate to hand_v2_middle_finger_middle_v1 -->
  <joint name="middle_2" type="revolute">
    <origin xyz="0.00126047 0.0119819 8.67362e-19" rpy="-3.14159 -5.20288e-15 -1.81407e-17"/>
    <parent link="middle_finger_intermediate"/>
    <child link="hand_v2_middle_finger_middle_v1"/>
    <axis xyz="0 0 1"/>
    <limit effort="10" velocity="10" lower="-3.55271e-15" upper="0.785398"/>
  </joint>
  <!-- Joint from palm_solid to middle_finger_intermediate -->
  <joint name="middle_1" type="revolute">
    <origin xyz="0.120528 0.00600672 -0.0354885" rpy="-3.14159 -0.159882 1.48524"/>
    <parent link="palm_solid"/>
    <child link="middle_finger_intermediate"/>
    <axis xyz="0 0 1"/>
    <limit effort="10" velocity="10" lower="-0.785398" upper="3.55271e-15"/>
    <mimic joint="middle_2" multiplier="-1.0"/>
  </joint>
  <!-- Link ring_finger_intermediate -->
  <link name="ring_finger_intermediate">
    <inertial>
      <origin xyz="0 0 0" rpy="0 0 0"/>
      <mass value="1e-09"/>
      <inertia ixx="1e-09" ixy="0" ixz="0" iyy="1e-09" iyz="0" izz="1e-09"/>
    </inertial>
    <!-- Part ring_finger_intermediate -->
    <visual>
      <origin xyz="0.0163093 -0.0699225 -0.01635" rpy="-0.184188 1.2871 -2.89869e-17"/>
      <geometry>
        <mesh filename="package://assets\ring_finger_intermediate.stl"/>
      </geometry>
      <material name="ring_finger_intermediate_material">
        <color rgba="0.768627 0.886275 0.952941 1"/>
      </material>
    </visual>
    <collision>
      <origin xyz="0.0163093 -0.0699225 -0.01635" rpy="-0.184188 1.2871 -2.89869e-17"/>
      <geometry>
        <mesh filename="package://assets\ring_finger_intermediate.stl"/>
      </geometry>
    </collision>
  </link>
  <!-- Link large_finger_middle -->
  <link name="large_finger_middle">
    <inertial>
      <origin xyz="0 0 0" rpy="0 0 0"/>
      <mass value="1e-09"/>
      <inertia ixx="1e-09" ixy="0" ixz="0" iyy="1e-09" iyz="0" izz="1e-09"/>
    </inertial>
    <!-- Part large_finger_middle -->
    <visual>
      <origin xyz="0.0186045 0.0817499 0.01635" rpy="2.9574 -1.2871 -4.88283e-17"/>
      <geometry>
        <mesh filename="package://assets\large_finger_middle.stl"/>
      </geometry>
      <material name="large_finger_middle_material">
        <color rgba="0.27451 0.270588 0.266667 1"/>
      </material>
    </visual>
    <collision>
      <origin xyz="0.0186045 0.0817499 0.01635" rpy="2.9574 -1.2871 -4.88283e-17"/>
      <geometry>
        <mesh filename="package://assets\large_finger_middle.stl"/>
      </geometry>
    </collision>
  </link>
  <!-- Link large_finger_tip -->
  <link name="large_finger_tip">
    <inertial>
      <origin xyz="0 0 0" rpy="0 0 0"/>
      <mass value="1e-09"/>
      <inertia ixx="1e-09" ixy="0" ixz="0" iyy="1e-09" iyz="0" izz="1e-09"/>
    </inertial>
    <!-- Part large_finger_tip -->
    <visual>
      <origin xyz="0.023367 0.106292 0.00635002" rpy="2.9574 -1.2871 5.2413e-17"/>
      <geometry>
        <mesh filename="package://assets\large_finger_tip.stl"/>
      </geometry>
      <material name="large_finger_tip_material">
        <color rgba="0.27451 0.270588 0.266667 1"/>
      </material>
    </visual>
    <collision>
      <origin xyz="0.023367 0.106292 0.00635002" rpy="2.9574 -1.2871 5.2413e-17"/>
      <geometry>
        <mesh filename="package://assets\large_finger_tip.stl"/>
      </geometry>
    </collision>
  </link>
  <!-- Joint from large_finger_middle to large_finger_tip -->
  <joint name="ring_3" type="revolute">
    <origin xyz="-0.00476256 -0.0245422 0.01" rpy="2.90536e-16 3.7697e-16 0.0810933"/>
    <parent link="large_finger_middle"/>
    <child link="large_finger_tip"/>
    <axis xyz="0 0 1"/>
    <limit effort="10" velocity="10" lower="-0.0810933" upper="1.83877"/>
  </joint>
  <!-- Joint from ring_finger_intermediate to large_finger_middle -->
  <joint name="ring_2" type="revolute">
    <origin xyz="-0.00229517 0.0118273 2.08167e-17" rpy="3.14159 -7.59416e-15 -1.18635e-16"/>
    <parent link="ring_finger_intermediate"/>
    <child link="large_finger_middle"/>
    <axis xyz="0 0 1"/>
    <limit effort="10" velocity="10" lower="-2.57572e-14" upper="0.785398"/>
    <mimic joint="ring_1" multiplier="-1.0"/>
  </joint>
  <!-- Joint from palm_solid to ring_finger_intermediate -->
  <joint name="ring_1" type="revolute">
    <origin xyz="0.113668 0.0118056 -0.0559307" rpy="-3.14159 -0.283692 1.77291"/>
    <parent link="palm_solid"/>
    <child link="ring_finger_intermediate"/>
    <axis xyz="0 0 1"/>
    <limit effort="10" velocity="10" lower="-0.785398" upper="2.57572e-14"/>
  </joint>
  <!-- Joint from intermediate_link to palm_solid -->
  <joint name="wrist_2" type="revolute">
    <origin xyz="0.025196 -0.000451714 -1.80411e-16" rpy="-3.14159 4.29642e-17 -0.0179261"/>
    <parent link="intermediate_link"/>
    <child link="palm_solid"/>
    <axis xyz="0 0 1"/>
    <limit effort="10" velocity="10" lower="-0.803324" upper="0.767472"/>
    <mimic joint="wrist_1" multiplier="-1.0"/>
  </joint>
  <!-- Joint from base to intermediate_link -->
  <joint name="wrist_1" type="revolute">
    <origin xyz="-0.0522 -0.03416 5.96745e-16" rpy="-1.5708 3.42121e-30 1.18329e-30"/>
    <parent link="base"/>
    <child link="intermediate_link"/>
    <axis xyz="0 0 1"/>
    <limit effort="10" velocity="10" lower="-0.767472" upper="0.803324"/>
  </joint>
</robot>
